Workbook

Sheet 재고현황_대시보드
A1: 원부자재 재고·생산·BOM·발주 실시간 통합 대시보드 (MRP)
A2: ※ BOM 정규형 기준 자동 생산차감(백플러시), 가용재고 및 실시간 병목 분석, 생산계획 시뮬레이션 연동
A4: 총 관리 부품수 | C4: 현재고 부족 부품 | E4: 안전재고 주의 부품 | G4: 즉시 생산가능 완제품 | I4: 총 발주 필요량 | L4: 미입고 발주 예정량
A5: =COUNTA(B10:B23)&" 개 품목" | C5: =COUNTIF(N10:N23,"부족")&" 개 품목" | E5: =COUNTIF(N10:N23,"주의")&" 개 품목" | G5: =COUNTIF(C29:C34,">0")&" / "&COUNTA(A29:A34)&" 종" | I5: =TEXT(SUM(O10:O23),"#,##0")&" EA" | L5: =TEXT(SUM(J10:J23),"#,##0")&" EA"
A8: ■ 실시간 원부자재 수불 현황 및 재고 과부족 분석 (단위: EA)
A9: 부품코드 | B9: 부품명 | C9: 부품구분 | D9: 단위 | E9: 기초재고 | F9: 입고누계 | G9: 기타출고 | H9: 생산차감 | I9: 현재고 | J9: 미입고예정 | K9: 가용재고 | L9: 안전재고 | M9: 목표재고 | N9: 재고상태 | O9: 필요발주량
A10: =품목_기준정보!A6 | B10: =품목_기준정보!B6 | C10: =품목_기준정보!C6 | D10: =품목_기준정보!D6 | E10: =품목_기준정보!E6 | F10: =SUMIFS(자재_입출고원장!$G$4:$G$100,자재_입출고원장!$E$4:$E$100,B10,자재_입출고원장!$C$4:$C$100,"입고") | G10: =SUMIFS(자재_입출고원장!$H$4:$H$100,자재_입출고원장!$E$4:$E$100,B10,자재_입출고원장!$C$4:$C$100,"출고") | H10: =SUMIFS(BOM_정규형!$I$4:$I$100,BOM_정규형!$D$4:$D$100,B10) | I10: =E10+F10-G10-H10 | J10: =SUMIFS(발주_미입고관리!$H$4:$H$100,발주_미입고관리!$D$4:$D$100,B10) | K10: =I10+J10 | L10: =품목_기준정보!F6 | M10: =품목_기준정보!G6 | N10: =IF(I10<0,"부족",IF(I10<L10,"주의","정상")) | O10: =MAX(M10-I10-J10,0)
A11: =품목_기준정보!A7 | B11: =품목_기준정보!B7 | C11: =품목_기준정보!C7 | D11: =품목_기준정보!D7 | E11: =품목_기준정보!E7 | F11: =SUMIFS(자재_입출고원장!$G$4:$G$100,자재_입출고원장!$E$4:$E$100,B11,자재_입출고원장!$C$4:$C$100,"입고") | G11: =SUMIFS(자재_입출고원장!$H$4:$H$100,자재_입출고원장!$E$4:$E$100,B11,자재_입출고원장!$C$4:$C$100,"출고") | H11: =SUMIFS(BOM_정규형!$I$4:$I$100,BOM_정규형!$D$4:$D$100,B11) | I11: =E11+F11-G11-H11 | J11: =SUMIFS(발주_미입고관리!$H$4:$H$100,발주_미입고관리!$D$4:$D$100,B11) | K11: =I11+J11 | L11: =품목_기준정보!F7 | M11: =품목_기준정보!G7 | N11: =IF(I11<0,"부족",IF(I11<L11,"주의","정상")) | O11: =MAX(M11-I11-J11,0)
A12: =품목_기준정보!A8 | B12: =품목_기준정보!B8 | C12: =품목_기준정보!C8 | D12: =품목_기준정보!D8 | E12: =품목_기준정보!E8 | F12: =SUMIFS(자재_입출고원장!$G$4:$G$100,자재_입출고원장!$E$4:$E$100,B12,자재_입출고원장!$C$4:$C$100,"입고") | G12: =SUMIFS(자재_입출고원장!$H$4:$H$100,자재_입출고원장!$E$4:$E$100,B12,자재_입출고원장!$C$4:$C$100,"출고") | H12: =SUMIFS(BOM_정규형!$I$4:$I$100,BOM_정규형!$D$4:$D$100,B12) | I12: =E12+F12-G12-H12 | J12: =SUMIFS(발주_미입고관리!$H$4:$H$100,발주_미입고관리!$D$4:$D$100,B12) | K12: =I12+J12 | L12: =품목_기준정보!F8 | M12: =품목_기준정보!G8 | N12: =IF(I12<0,"부족",IF(I12<L12,"주의","정상")) | O12: =MAX(M12-I12-J12,0)
A13: =품목_기준정보!A9 | B13: =품목_기준정보!B9 | C13: =품목_기준정보!C9 | D13: =품목_기준정보!D9 | E13: =품목_기준정보!E9 | F13: =SUMIFS(자재_입출고원장!$G$4:$G$100,자재_입출고원장!$E$4:$E$100,B13,자재_입출고원장!$C$4:$C$100,"입고") | G13: =SUMIFS(자재_입출고원장!$H$4:$H$100,자재_입출고원장!$E$4:$E$100,B13,자재_입출고원장!$C$4:$C$100,"출고") | H13: =SUMIFS(BOM_정규형!$I$4:$I$100,BOM_정규형!$D$4:$D$100,B13) | I13: =E13+F13-G13-H13 | J13: =SUMIFS(발주_미입고관리!$H$4:$H$100,발주_미입고관리!$D$4:$D$100,B13) | K13: =I13+J13 | L13: =품목_기준정보!F9 | M13: =품목_기준정보!G9 | N13: =IF(I13<0,"부족",IF(I13<L13,"주의","정상")) | O13: =MAX(M13-I13-J13,0)
A14: =품목_기준정보!A10 | B14: =품목_기준정보!B10 | C14: =품목_기준정보!C10 | D14: =품목_기준정보!D10 | E14: =품목_기준정보!E10 | F14: =SUMIFS(자재_입출고원장!$G$4:$G$100,자재_입출고원장!$E$4:$E$100,B14,자재_입출고원장!$C$4:$C$100,"입고") | G14: =SUMIFS(자재_입출고원장!$H$4:$H$100,자재_입출고원장!$E$4:$E$100,B14,자재_입출고원장!$C$4:$C$100,"출고") | H14: =SUMIFS(BOM_정규형!$I$4:$I$100,BOM_정규형!$D$4:$D$100,B14) | I14: =E14+F14-G14-H14 | J14: =SUMIFS(발주_미입고관리!$H$4:$H$100,발주_미입고관리!$D$4:$D$100,B14) | K14: =I14+J14 | L14: =품목_기준정보!F10 | M14: =품목_기준정보!G10 | N14: =IF(I14<0,"부족",IF(I14<L14,"주의","정상")) | O14: =MAX(M14-I14-J14,0)
A15: =품목_기준정보!A11 | B15: =품목_기준정보!B11 | C15: =품목_기준정보!C11 | D15: =품목_기준정보!D11 | E15: =품목_기준정보!E11 | F15: =SUMIFS(자재_입출고원장!$G$4:$G$100,자재_입출고원장!$E$4:$E$100,B15,자재_입출고원장!$C$4:$C$100,"입고") | G15: =SUMIFS(자재_입출고원장!$H$4:$H$100,자재_입출고원장!$E$4:$E$100,B15,자재_입출고원장!$C$4:$C$100,"출고") | H15: =SUMIFS(BOM_정규형!$I$4:$I$100,BOM_정규형!$D$4:$D$100,B15) | I15: =E15+F15-G15-H15 | J15: =SUMIFS(발주_미입고관리!$H$4:$H$100,발주_미입고관리!$D$4:$D$100,B15) | K15: =I15+J15 | L15: =품목_기준정보!F11 | M15: =품목_기준정보!G11 | N15: =IF(I15<0,"부족",IF(I15<L15,"주의","정상")) | O15: =MAX(M15-I15-J15,0)
A16: =품목_기준정보!A12 | B16: =품목_기준정보!B12 | C16: =품목_기준정보!C12 | D16: =품목_기준정보!D12 | E16: =품목_기준정보!E12 | F16: =SUMIFS(자재_입출고원장!$G$4:$G$100,자재_입출고원장!$E$4:$E$100,B16,자재_입출고원장!$C$4:$C$100,"입고") | G16: =SUMIFS(자재_입출고원장!$H$4:$H$100,자재_입출고원장!$E$4:$E$100,B16,자재_입출고원장!$C$4:$C$100,"출고") | H16: =SUMIFS(BOM_정규형!$I$4:$I$100,BOM_정규형!$D$4:$D$100,B16) | I16: =E16+F16-G16-H16 | J16: =SUMIFS(발주_미입고관리!$H$4:$H$100,발주_미입고관리!$D$4:$D$100,B16) | K16: =I16+J16 | L16: =품목_기준정보!F12 | M16: =품목_기준정보!G12 | N16: =IF(I16<0,"부족",IF(I16<L16,"주의","정상")) | O16: =MAX(M16-I16-J16,0)
A17: =품목_기준정보!A13 | B17: =품목_기준정보!B13 | C17: =품목_기준정보!C13 | D17: =품목_기준정보!D13 | E17: =품목_기준정보!E13 | F17: =SUMIFS(자재_입출고원장!$G$4:$G$100,자재_입출고원장!$E$4:$E$100,B17,자재_입출고원장!$C$4:$C$100,"입고") | G17: =SUMIFS(자재_입출고원장!$H$4:$H$100,자재_입출고원장!$E$4:$E$100,B17,자재_입출고원장!$C$4:$C$100,"출고") | H17: =SUMIFS(BOM_정규형!$I$4:$I$100,BOM_정규형!$D$4:$D$100,B17) | I17: =E17+F17-G17-H17 | J17: =SUMIFS(발주_미입고관리!$H$4:$H$100,발주_미입고관리!$D$4:$D$100,B17) | K17: =I17+J17 | L17: =품목_기준정보!F13 | M17: =품목_기준정보!G13 | N17: =IF(I17<0,"부족",IF(I17<L17,"주의","정상")) | O17: =MAX(M17-I17-J17,0)
A18: =품목_기준정보!A14 | B18: =품목_기준정보!B14 | C18: =품목_기준정보!C14 | D18: =품목_기준정보!D14 | E18: =품목_기준정보!E14 | F18: =SUMIFS(자재_입출고원장!$G$4:$G$100,자재_입출고원장!$E$4:$E$100,B18,자재_입출고원장!$C$4:$C$100,"입고") | G18: =SUMIFS(자재_입출고원장!$H$4:$H$100,자재_입출고원장!$E$4:$E$100,B18,자재_입출고원장!$C$4:$C$100,"출고") | H18: =SUMIFS(BOM_정규형!$I$4:$I$100,BOM_정규형!$D$4:$D$100,B18) | I18: =E18+F18-G18-H18 | J18: =SUMIFS(발주_미입고관리!$H$4:$H$100,발주_미입고관리!$D$4:$D$100,B18) | K18: =I18+J18 | L18: =품목_기준정보!F14 | M18: =품목_기준정보!G14 | N18: =IF(I18<0,"부족",IF(I18<L18,"주의","정상")) | O18: =MAX(M18-I18-J18,0)
A19: =품목_기준정보!A15 | B19: =품목_기준정보!B15 | C19: =품목_기준정보!C15 | D19: =품목_기준정보!D15 | E19: =품목_기준정보!E15 | F19: =SUMIFS(자재_입출고원장!$G$4:$G$100,자재_입출고원장!$E$4:$E$100,B19,자재_입출고원장!$C$4:$C$100,"입고") | G19: =SUMIFS(자재_입출고원장!$H$4:$H$100,자재_입출고원장!$E$4:$E$100,B19,자재_입출고원장!$C$4:$C$100,"출고") | H19: =SUMIFS(BOM_정규형!$I$4:$I$100,BOM_정규형!$D$4:$D$100,B19) | I19: =E19+F19-G19-H19 | J19: =SUMIFS(발주_미입고관리!$H$4:$H$100,발주_미입고관리!$D$4:$D$100,B19) | K19: =I19+J19 | L19: =품목_기준정보!F15 | M19: =품목_기준정보!G15 | N19: =IF(I19<0,"부족",IF(I19<L19,"주의","정상")) | O19: =MAX(M19-I19-J19,0)
A20: =품목_기준정보!A16 | B20: =품목_기준정보!B16 | C20: =품목_기준정보!C16 | D20: =품목_기준정보!D16 | E20: =품목_기준정보!E16 | F20: =SUMIFS(자재_입출고원장!$G$4:$G$100,자재_입출고원장!$E$4:$E$100,B20,자재_입출고원장!$C$4:$C$100,"입고") | G20: =SUMIFS(자재_입출고원장!$H$4:$H$100,자재_입출고원장!$E$4:$E$100,B20,자재_입출고원장!$C$4:$C$100,"출고") | H20: =SUMIFS(BOM_정규형!$I$4:$I$100,BOM_정규형!$D$4:$D$100,B20) | I20: =E20+F20-G20-H20 | J20: =SUMIFS(발주_미입고관리!$H$4:$H$100,발주_미입고관리!$D$4:$D$100,B20) | K20: =I20+J20 | L20: =품목_기준정보!F16 | M20: =품목_기준정보!G16 | N20: =IF(I20<0,"부족",IF(I20<L20,"주의","정상")) | O20: =MAX(M20-I20-J20,0)
A21: =품목_기준정보!A17 | B21: =품목_기준정보!B17 | C21: =품목_기준정보!C17 | D21: =품목_기준정보!D17 | E21: =품목_기준정보!E17 | F21: =SUMIFS(자재_입출고원장!$G$4:$G$100,자재_입출고원장!$E$4:$E$100,B21,자재_입출고원장!$C$4:$C$100,"입고") | G21: =SUMIFS(자재_입출고원장!$H$4:$H$100,자재_입출고원장!$E$4:$E$100,B21,자재_입출고원장!$C$4:$C$100,"출고") | H21: =SUMIFS(BOM_정규형!$I$4:$I$100,BOM_정규형!$D$4:$D$100,B21) | I21: =E21+F21-G21-H21 | J21: =SUMIFS(발주_미입고관리!$H$4:$H$100,발주_미입고관리!$D$4:$D$100,B21) | K21: =I21+J21 | L21: =품목_기준정보!F17 | M21: =품목_기준정보!G17 | N21: =IF(I21<0,"부족",IF(I21<L21,"주의","정상")) | O21: =MAX(M21-I21-J21,0)
... A23: =품목_기준정보!A19 | B23: =품목_기준정보!B19 | C23: =품목_기준정보!C19 | D23: =품목_기준정보!D19 | E23: =품목_기준정보!E19 | F23: =SUMIFS(자재_입출고원장!$G$4:$G$100,자재_입출고원장!$E$4:$E$100,B23,자재_입출고원장!$C$4:$C$100,"입고") | G23: =SUMIFS(자재_입출고원장!$H$4:$H$100,자재_입출고원장!$E$4:$E$100,B23,자재_입출고원장!$C$4:$C$100,"출고") | H23: =SUMIFS(BOM_정규형!$I$4:$I$100,BOM_정규형!$D$4:$D$100,B23) | I23: =E23+F23-G23-H23 | J23: =SUMIFS(발주_미입고관리!$H$4:$H$100,발주_미입고관리!$D$4:$D$100,B23) | K23: =I23+J23 | L23: =품목_기준정보!F19 | M23: =품목_기준정보!G19 | N23: =IF(I23<0,"부족",IF(I23<L23,"주의","정상")) | O23: =MAX(M23-I23-J23,0)
A24: 합계 | E24: =SUM(E10:E23) | F24: =SUM(F10:F23) | G24: =SUM(G10:G23) | H24: =SUM(H10:H23) | I24: =SUM(I10:I23) | J24: =SUM(J10:J23) | K24: =SUM(K10:K23) | L24: =SUM(L10:L23) | M24: =SUM(M10:M23) | N24: ="부족 "&COUNTIF(N10:N23,"부족")&"건 / 주의 "&COUNTIF(N10:N23,"주의")&"건" | O24: =SUM(O10:O23)
A27: ■ 완제품별 실시간 생산 가용성 및 병목 분석 (단위: Set)
A28: 완제품코드 | B28: 완제품명 | C28: 0 | D28: 병목부품 | E28: 생산가능 여부 | F28: 잠재 생산가능량(가용재고) | G28: 생산 가용성 분석 비고
A29: FG-001 | B29: =품목_기준정보!B24 | C29: 5000 | D29: =INDEX(BOM_정규형!$D$4:$D$100,MATCH(1,INDEX((BOM_정규형!$A$4:$A$100=A29)*(BOM_정규형!$N$4:$N$100=C29),),0)) | E29: =IF(C29>0,"정상 생산 가능","생산 불가 (결품)") | F29: =_xlfn.MINIFS(BOM_정규형!$O$4:$O$100,BOM_정규형!$A$4:$A$100,A29) | G29: =IF(C29>0,"현재고 기준 "&TEXT(C29,"#,##0")&" Set 가능 (병목: "&D29&")","생산 불가 ("&D29&" 재고 부족)")
A30: FG-002 | B30: =품목_기준정보!B25 | C30: 1000 | D30: =INDEX(BOM_정규형!$D$4:$D$100,MATCH(1,INDEX((BOM_정규형!$A$4:$A$100=A30)*(BOM_정규형!$N$4:$N$100=C30),),0)) | E30: =IF(C30>0,"정상 생산 가능","생산 불가 (결품)") | F30: =_xlfn.MINIFS(BOM_정규형!$O$4:$O$100,BOM_정규형!$A$4:$A$100,A30) | G30: =IF(C30>0,"현재고 기준 "&TEXT(C30,"#,##0")&" Set 가능 (병목: "&D30&")","생산 불가 ("&D30&" 재고 부족)")
A31: FG-003 | B31: =품목_기준정보!B26 | C31: 0 | D31: =INDEX(BOM_정규형!$D$4:$D$100,MATCH(1,INDEX((BOM_정규형!$A$4:$A$100=A31)*(BOM_정규형!$N$4:$N$100=C31),),0)) | E31: =IF(C31>0,"정상 생산 가능","생산 불가 (결품)") | F31: =_xlfn.MINIFS(BOM_정규형!$O$4:$O$100,BOM_정규형!$A$4:$A$100,A31) | G31: =IF(C31>0,"현재고 기준 "&TEXT(C31,"#,##0")&" Set 가능 (병목: "&D31&")","생산 불가 ("&D31&" 재고 부족)")
A32: FG-004 | B32: =품목_기준정보!B27 | C32: 0 | D32: =INDEX(BOM_정규형!$D$4:$D$100,MATCH(1,INDEX((BOM_정규형!$A$4:$A$100=A32)*(BOM_정규형!$N$4:$N$100=C32),),0)) | E32: =IF(C32>0,"정상 생산 가능","생산 불가 (결품)") | F32: =_xlfn.MINIFS(BOM_정규형!$O$4:$O$100,BOM_정규형!$A$4:$A$100,A32) | G32: =IF(C32>0,"현재고 기준 "&TEXT(C32,"#,##0")&" Set 가능 (병목: "&D32&")","생산 불가 ("&D32&" 재고 부족)")
A33: FG-005 | B33: =품목_기준정보!B28 | C33: 0 | D33: =INDEX(BOM_정규형!$D$4:$D$100,MATCH(1,INDEX((BOM_정규형!$A$4:$A$100=A33)*(BOM_정규형!$N$4:$N$100=C33),),0)) | E33: =IF(C33>0,"정상 생산 가능","생산 불가 (결품)") | F33: =_xlfn.MINIFS(BOM_정규형!$O$4:$O$100,BOM_정규형!$A$4:$A$100,A33) | G33: =IF(C33>0,"현재고 기준 "&TEXT(C33,"#,##0")&" Set 가능 (병목: "&D33&")","생산 불가 ("&D33&" 재고 부족)")
A34: FG-006 | B34: =품목_기준정보!B29 | C34: 0 | D34: =INDEX(BOM_정규형!$D$4:$D$100,MATCH(1,INDEX((BOM_정규형!$A$4:$A$100=A34)*(BOM_정규형!$N$4:$N$100=C34),),0)) | E34: =IF(C34>0,"정상 생산 가능","생산 불가 (결품)") | F34: =_xlfn.MINIFS(BOM_정규형!$O$4:$O$100,BOM_정규형!$A$4:$A$100,A34) | G34: =IF(C34>0,"현재고 기준 "&TEXT(C34,"#,##0")&" Set 가능 (병목: "&D34&")","생산 불가 ("&D34&" 재고 부족)")
A35: 합계 | B35: 제품별 최대 생산가능량 합계 (※ 공통부품을 공유하므로 전 품목 동시 생산량이 아님) | C35: =SUM(C29:C34) | E35: ="가용 "&COUNTIF(C29:C34,">0")&"종 / 전체 "&COUNTA(A29:A34)&"종" | F35: =SUM(F29:F34)
A38: ■ 완제품 생산 계획 수량 시뮬레이션 (단위: Set)
A39: 완제품코드 | B39: 완제품명 | C39: 생산계획수량 | D39: 현재고 기준 최대가능량 | E39: 생산가능 여부 | F39: 계획 부족량 | G39: 시뮬레이션 비고
A40: FG-001 | B40: =품목_기준정보!B24 | C40: 300 | D40: =C29 | E40: =IF(C40=0,"-",IF(C40<=D40,"생산 가능","생산 불가 (부족)")) | F40: =IF(C40<=D40,0,C40-D40) | G40: =IF(C40=0,"계획 없음",IF(C40<=D40,"가용 재고 충족","가용량 대비 "&TEXT(F40,"#,##0")&" Set 부족"))
A41: FG-002 | B41: =품목_기준정보!B25 | C41: 0 | D41: =C30 | E41: =IF(C41=0,"-",IF(C41<=D41,"생산 가능","생산 불가 (부족)")) | F41: =IF(C41<=D41,0,C41-D41) | G41: =IF(C41=0,"계획 없음",IF(C41<=D41,"가용 재고 충족","가용량 대비 "&TEXT(F41,"#,##0")&" Set 부족"))
A42: FG-003 | B42: =품목_기준정보!B26 | C42: 100 | D42: =C31 | E42: =IF(C42=0,"-",IF(C42<=D42,"생산 가능","생산 불가 (부족)")) | F42: =IF(C42<=D42,0,C42-D42) | G42: =IF(C42=0,"계획 없음",IF(C42<=D42,"가용 재고 충족","가용량 대비 "&TEXT(F42,"#,##0")&" Set 부족"))
A43: FG-004 | B43: =품목_기준정보!B27 | C43: 500 | D43: =C32 | E43: =IF(C43=0,"-",IF(C43<=D43,"생산 가능","생산 불가 (부족)")) | F43: =IF(C43<=D43,0,C43-D43) | G43: =IF(C43=0,"계획 없음",IF(C43<=D43,"가용 재고 충족","가용량 대비 "&TEXT(F43,"#,##0")&" Set 부족"))
A44: FG-005 | B44: =품목_기준정보!B28 | C44: 0 | D44: =C33 | E44: =IF(C44=0,"-",IF(C44<=D44,"생산 가능","생산 불가 (부족)")) | F44: =IF(C44<=D44,0,C44-D44) | G44: =IF(C44=0,"계획 없음",IF(C44<=D44,"가용 재고 충족","가용량 대비 "&TEXT(F44,"#,##0")&" Set 부족"))
A45: FG-006 | B45: =품목_기준정보!B29 | C45: 0 | D45: =C34 | E45: =IF(C45=0,"-",IF(C45<=D45,"생산 가능","생산 불가 (부족)")) | F45: =IF(C45<=D45,0,C45-D45) | G45: =IF(C45=0,"계획 없음",IF(C45<=D45,"가용 재고 충족","가용량 대비 "&TEXT(F45,"#,##0")&" Set 부족"))
A46: 합계 | C46: =SUM(C40:C45) | D46: =SUM(D40:D45) | E46: =IF(COUNTIF(E40:E45,"생산 불가 (부족)")>0,"일부 초과 ("&COUNTIF(E40:E45,"생산 불가 (부족)")&"건)","전체 생산 가능") | F46: =SUM(F40:F45) | G46: ="계획 총 "&TEXT(C46,"#,##0")&" Set / 부족 총 "&TEXT(F46,"#,##0")&" Set"
A49: ■ 생산계획에 따른 부품별 계획 소요량 및 과부족 분석 (단위: EA)
A50: 부품코드 | B50: 부품명 | C50: 부품구분 | D50: 단위 | E50: 현재고 | F50: 계획 총소요량 | G50: 예상 잔여재고 | H50: 과부족 판정 | I50: 계획 기준 추가발주량
...

Sheet 품목_기준정보
A1: 품목 기준정보 마스터 (원부자재 & 완제품)
A2: ※ 모든 품목의 기본 규격, 기초재고, 안전재고, 목표재고를 관리하는 단일 기준정보(Master Data)입니다.
A4: ■ 원부자재 기준정보 마스터 (14개 관리 부품)
A5: 부품코드 | B5: 부품명 | C5: 부품구분 | D5: 단위 | E5: 기초재고 | F5: 안전재고 | G5: 목표재고 | H5: 리드타임(일) | I5: 비고
A6: RM-GL-01 | B6: 블랙삼각선반 | C6: 유리선반 | D6: EA | E6: 375 | F6: 100 | G6: 200 | H6: 5 | I6: 본체 (블랙 삼각)
A7: RM-GL-02 | B7: 블랙일자선반 | C7: 유리선반 | D7: EA | E7: 200 | F7: 50 | G7: 100 | H7: 5 | I7: 본체 (블랙 일자)
A8: RM-GL-03 | B8: 블랙오각선반 | C8: 유리선반 | D8: EA | E8: 1150 | F8: 50 | G8: 100 | H8: 5 | I8: 본체 (블랙 오각)
A9: RM-GL-04 | B9: 그린삼각선반 | C9: 유리선반 | D9: EA | E9: 525 | F9: 50 | G9: 100 | H9: 5 | I9: 본체 (그린 삼각)
A10: RM-GL-05 | B10: 그린일자선반 | C10: 유리선반 | D10: EA | E10: 280 | F10: 50 | G10: 100 | H10: 5 | I10: 본체 (그린 일자)
A11: RM-GL-06 | B11: 그린오각선반 | C11: 유리선반 | D11: EA | E11: 850 | F11: 50 | G11: 100 | H11: 5 | I11: 본체 (그린 오각)
A12: RM-GD-01 | B12: 블랙코너선반가이드 | C12: 선반가이드 | D12: EA | E12: 500 | F12: 50 | G12: 100 | H12: 3 | I12: 블랙 라운드 가이드
A13: RM-GD-02 | B13: 블랙일자선반가이드 | C13: 선반가이드 | D13: EA | E13: 0 | F13: 50 | G13: 100 | H13: 3 | I13: 블랙 일자 가이드
A14: RM-GD-03 | B14: 크롬코너선반가이드 | C14: 선반가이드 | D14: EA | E14: 1250 | F14: 50 | G14: 100 | H14: 3 | I14: 크롬 라운드 가이드
A15: RM-GD-04 | B15: 크롬일자선반가이드 | C15: 선반가이드 | D15: EA | E15: 0 | F15: 50 | G15: 100 | H15: 3 | I15: 크롬 일자 가이드
A16: RM-BK-01 | B16: 블랙선반브라켓 | C16: 선반브라켓 | D16: EA | E16: 1824 | F16: 100 | G16: 200 | H16: 7 | I16: 선반 고정 브라켓
A17: RM-BK-02 | B17: 크롬선반브라켓 | C17: 선반브라켓 | D17: EA | E17: 1600 | F17: 100 | G17: 200 | H17: 7 | I17: 선반 고정 브라켓
... A19: RM-MT-02 | B19: 칼브럭피스 | C19: 공통부자재 | D19: EA | E19: 1000 | F19: 200 | G19: 400 | H19: 2 | I19: 벽면 고정 부속 세트
A22: ■ 완제품 기준정보 마스터 (6개 양산 품목)
A23: 완제품코드 | B23: 완제품명 | C23: 규격/구분 | D23: 기본단위 | E23: 0 | F23: 0 | G23: 0 | H23: 5
A24: FG-001 | B24: 블랙코너선반 | C24: 블랙 / 삼각 | D24: Set | E24: 0 | F24: 0 | G24: 0 | H24: 5
A25: FG-002 | B25: 블랙일자선반 | C25: 블랙 / 일자 | D25: Set | E25: 0 | F25: 0 | G25: 0 | H25: 5
A26: FG-003 | B26: 블랙오각선반 | C26: 블랙 / 오각 | D26: Set | E26: 0 | F26: 0 | G26: 0 | H26: 5
A27: FG-004 | B27: 코너선반 | C27: 그린 / 삼각 | D27: Set | E27: 0 | F27: 0 | G27: 0 | H27: 5
A28: FG-005 | B28: 일자선반 | C28: 그린 / 일자 | D28: Set | E28: 0 | F28: 0 | G28: 0 | H28: 5
A29: FG-006 | B29: 오각선반 | C29: 그린 / 오각 | D29: Set | E29: 0 | F29: 0 | G29: 0 | H29: 5

Sheet BOM_정규형
A1: 표준 정규화 자재명세서 (BOM 정규형 마스터 & 연산 엔진)
A2: ※ 완제품코드와 부품소요량의 단일 기준(Single Source of Truth)이며 생산실적 및 계획과 자동 동기화됩니다.
A3: ■ BOM 정규형 소요원단위 및 실시간 전개(Explosion) 연산 엔진 테이블
A4: 완제품코드 | B4: 완제품명 | C4: 부품구분 | D4: 부품명 | E4: 소요원단위(EA) | F4: 단위 | G4: 비고 | H4: 누적생산수량 | I4: 생산소요량 | J4: 계획생산수량 | K4: 계획소요량 | L4: 부품현재고 | M4: 부품가용재고 | N4: 현재고가능량 | O4: 가용재고가능량
A5: FG-001 | B5: =IFERROR(INDEX(품목_기준정보!$B$24:$B$35,MATCH(A5,품목_기준정보!$A$24:$A$35,0)),"") | C5: =IFERROR(INDEX(품목_기준정보!$C$6:$C$25,MATCH(D5,품목_기준정보!$B$6:$B$25,0)),"") | D5: 블랙삼각선반 | E5: 1 | F5: EA | G5: 본체 (블랙 삼각) | H5: =SUMIFS(생산_실적일지!$G$4:$G$100,생산_실적일지!$D$4:$D$100,A5) | I5: =E5*H5 | J5: =SUMIFS(재고현황_대시보드!$C$40:$C$45,재고현황_대시보드!$A$40:$A$45,A5) | K5: =E5*J5 | L5: =INDEX(재고현황_대시보드!$I$10:$I$23,MATCH(D5,재고현황_대시보드!$B$10:$B$23,0)) | M5: =INDEX(재고현황_대시보드!$K$10:$K$23,MATCH(D5,재고현황_대시보드!$B$10:$B$23,0)) | N5: =IF(E5>0,INT(L5/E5),0) | O5: =IF(E5>0,INT(M5/E5),0)
A6: FG-001 | B6: =IFERROR(INDEX(품목_기준정보!$B$24:$B$35,MATCH(A6,품목_기준정보!$A$24:$A$35,0)),"") | C6: =IFERROR(INDEX(품목_기준정보!$C$6:$C$25,MATCH(D6,품목_기준정보!$B$6:$B$25,0)),"") | D6: 블랙코너선반가이드 | E6: 1 | F6: EA | G6: 블랙 라운드 가이드 | H6: =SUMIFS(생산_실적일지!$G$4:$G$100,생산_실적일지!$D$4:$D$100,A6) | I6: =E6*H6 | J6: =SUMIFS(재고현황_대시보드!$C$40:$C$45,재고현황_대시보드!$A$40:$A$45,A6) | K6: =E6*J6 | L6: =INDEX(재고현황_대시보드!$I$10:$I$23,MATCH(D6,재고현황_대시보드!$B$10:$B$23,0)) | M6: =INDEX(재고현황_대시보드!$K$10:$K$23,MATCH(D6,재고현황_대시보드!$B$10:$B$23,0)) | N6: =IF(E6>0,INT(L6/E6),0) | O6: =IF(E6>0,INT(M6/E6),0)
A7: FG-001 | B7: =IFERROR(INDEX(품목_기준정보!$B$24:$B$35,MATCH(A7,품목_기준정보!$A$24:$A$35,0)),"") | C7: =IFERROR(INDEX(품목_기준정보!$C$6:$C$25,MATCH(D7,품목_기준정보!$B$6:$B$25,0)),"") | D7: 블랙선반브라켓 | E7: 2 | F7: EA | G7: 선반 고정 브라켓 | H7: =SUMIFS(생산_실적일지!$G$4:$G$100,생산_실적일지!$D$4:$D$100,A7) | I7: =E7*H7 | J7: =SUMIFS(재고현황_대시보드!$C$40:$C$45,재고현황_대시보드!$A$40:$A$45,A7) | K7: =E7*J7 | L7: =INDEX(재고현황_대시보드!$I$10:$I$23,MATCH(D7,재고현황_대시보드!$B$10:$B$23,0)) | M7: =INDEX(재고현황_대시보드!$K$10:$K$23,MATCH(D7,재고현황_대시보드!$B$10:$B$23,0)) | N7: =IF(E7>0,INT(L7/E7),0) | O7: =IF(E7>0,INT(M7/E7),0)
A8: FG-001 | B8: =IFERROR(INDEX(품목_기준정보!$B$24:$B$35,MATCH(A8,품목_기준정보!$A$24:$A$35,0)),"") | C8: =IFERROR(INDEX(품목_기준정보!$C$6:$C$25,MATCH(D8,품목_기준정보!$B$6:$B$25,0)),"") | D8: 비닐 | E8: 1 | F8: EA | G8: 개별 포장용 비닐 | H8: =SUMIFS(생산_실적일지!$G$4:$G$100,생산_실적일지!$D$4:$D$100,A8) | I8: =E8*H8 | J8: =SUMIFS(재고현황_대시보드!$C$40:$C$45,재고현황_대시보드!$A$40:$A$45,A8) | K8: =E8*J8 | L8: =INDEX(재고현황_대시보드!$I$10:$I$23,MATCH(D8,재고현황_대시보드!$B$10:$B$23,0)) | M8: =INDEX(재고현황_대시보드!$K$10:$K$23,MATCH(D8,재고현황_대시보드!$B$10:$B$23,0)) | N8: =IF(E8>0,INT(L8/E8),0) | O8: =IF(E8>0,INT(M8/E8),0)
A9: FG-001 | B9: =IFERROR(INDEX(품목_기준정보!$B$24:$B$35,MATCH(A9,품목_기준정보!$A$24:$A$35,0)),"") | C9: =IFERROR(INDEX(품목_기준정보!$C$6:$C$25,MATCH(D9,품목_기준정보!$B$6:$B$25,0)),"") | D9: 칼브럭피스 | E9: 1 | F9: EA | G9: 벽면 고정 부속 세트 | H9: =SUMIFS(생산_실적일지!$G$4:$G$100,생산_실적일지!$D$4:$D$100,A9) | I9: =E9*H9 | J9: =SUMIFS(재고현황_대시보드!$C$40:$C$45,재고현황_대시보드!$A$40:$A$45,A9) | K9: =E9*J9 | L9: =INDEX(재고현황_대시보드!$I$10:$I$23,MATCH(D9,재고현황_대시보드!$B$10:$B$23,0)) | M9: =INDEX(재고현황_대시보드!$K$10:$K$23,MATCH(D9,재고현황_대시보드!$B$10:$B$23,0)) | N9: =IF(E9>0,INT(L9/E9),0) | O9: =IF(E9>0,INT(M9/E9),0)
A10: FG-002 | B10: =IFERROR(INDEX(품목_기준정보!$B$24:$B$35,MATCH(A10,품목_기준정보!$A$24:$A$35,0)),"") | C10: =IFERROR(INDEX(품목_기준정보!$C$6:$C$25,MATCH(D10,품목_기준정보!$B$6:$B$25,0)),"") | D10: 블랙일자선반 | E10: 1 | F10: EA | G10: 본체 (블랙 일자) | H10: =SUMIFS(생산_실적일지!$G$4:$G$100,생산_실적일지!$D$4:$D$100,A10) | I10: =E10*H10 | J10: =SUMIFS(재고현황_대시보드!$C$40:$C$45,재고현황_대시보드!$A$40:$A$45,A10) | K10: =E10*J10 | L10: =INDEX(재고현황_대시보드!$I$10:$I$23,MATCH(D10,재고현황_대시보드!$B$10:$B$23,0)) | M10: =INDEX(재고현황_대시보드!$K$10:$K$23,MATCH(D10,재고현황_대시보드!$B$10:$B$23,0)) | N10: =IF(E10>0,INT(L10/E10),0) | O10: =IF(E10>0,INT(M10/E10),0)
A11: FG-002 | B11: =IFERROR(INDEX(품목_기준정보!$B$24:$B$35,MATCH(A11,품목_기준정보!$A$24:$A$35,0)),"") | C11: =IFERROR(INDEX(품목_기준정보!$C$6:$C$25,MATCH(D11,품목_기준정보!$B$6:$B$25,0)),"") | D11: 블랙일자선반가이드 | E11: 2 | F11: EA | G11: 일자선반 가이드 2개 | H11: =SUMIFS(생산_실적일지!$G$4:$G$100,생산_실적일지!$D$4:$D$100,A11) | I11: =E11*H11 | J11: =SUMIFS(재고현황_대시보드!$C$40:$C$45,재고현황_대시보드!$A$40:$A$45,A11) | K11: =E11*J11 | L11: =INDEX(재고현황_대시보드!$I$10:$I$23,MATCH(D11,재고현황_대시보드!$B$10:$B$23,0)) | M11: =INDEX(재고현황_대시보드!$K$10:$K$23,MATCH(D11,재고현황_대시보드!$B$10:$B$23,0)) | N11: =IF(E11>0,INT(L11/E11),0) | O11: =IF(E11>0,INT(M11/E11),0)
A12: FG-002 | B12: =IFERROR(INDEX(품목_기준정보!$B$24:$B$35,MATCH(A12,품목_기준정보!$A$24:$A$35,0)),"") | C12: =IFERROR(INDEX(품목_기준정보!$C$6:$C$25,MATCH(D12,품목_기준정보!$B$6:$B$25,0)),"") | D12: 블랙선반브라켓 | E12: 2 | F12: EA | G12: 선반 고정 브라켓 | H12: =SUMIFS(생산_실적일지!$G$4:$G$100,생산_실적일지!$D$4:$D$100,A12) | I12: =E12*H12 | J12: =SUMIFS(재고현황_대시보드!$C$40:$C$45,재고현황_대시보드!$A$40:$A$45,A12) | K12: =E12*J12 | L12: =INDEX(재고현황_대시보드!$I$10:$I$23,MATCH(D12,재고현황_대시보드!$B$10:$B$23,0)) | M12: =INDEX(재고현황_대시보드!$K$10:$K$23,MATCH(D12,재고현황_대시보드!$B$10:$B$23,0)) | N12: =IF(E12>0,INT(L12/E12),0) | O12: =IF(E12>0,INT(M12/E12),0)
A13: FG-002 | B13: =IFERROR(INDEX(품목_기준정보!$B$24:$B$35,MATCH(A13,품목_기준정보!$A$24:$A$35,0)),"") | C13: =IFERROR(INDEX(품목_기준정보!$C$6:$C$25,MATCH(D13,품목_기준정보!$B$6:$B$25,0)),"") | D13: 비닐 | E13: 1 | F13: EA | G13: 개별 포장용 비닐 | H13: =SUMIFS(생산_실적일지!$G$4:$G$100,생산_실적일지!$D$4:$D$100,A13) | I13: =E13*H13 | J13: =SUMIFS(재고현황_대시보드!$C$40:$C$45,재고현황_대시보드!$A$40:$A$45,A13) | K13: =E13*J13 | L13: =INDEX(재고현황_대시보드!$I$10:$I$23,MATCH(D13,재고현황_대시보드!$B$10:$B$23,0)) | M13: =INDEX(재고현황_대시보드!$K$10:$K$23,MATCH(D13,재고현황_대시보드!$B$10:$B$23,0)) | N13: =IF(E13>0,INT(L13/E13),0) | O13: =IF(E13>0,INT(M13/E13),0)
A14: FG-002 | B14: =IFERROR(INDEX(품목_기준정보!$B$24:$B$35,MATCH(A14,품목_기준정보!$A$24:$A$35,0)),"") | C14: =IFERROR(INDEX(품목_기준정보!$C$6:$C$25,MATCH(D14,품목_기준정보!$B$6:$B$25,0)),"") | D14: 칼브럭피스 | E14: 1 | F14: EA | G14: 벽면 고정 부속 세트 | H14: =SUMIFS(생산_실적일지!$G$4:$G$100,생산_실적일지!$D$4:$D$100,A14) | I14: =E14*H14 | J14: =SUMIFS(재고현황_대시보드!$C$40:$C$45,재고현황_대시보드!$A$40:$A$45,A14) | K14: =E14*J14 | L14: =INDEX(재고현황_대시보드!$I$10:$I$23,MATCH(D14,재고현황_대시보드!$B$10:$B$23,0)) | M14: =INDEX(재고현황_대시보드!$K$10:$K$23,MATCH(D14,재고현황_대시보드!$B$10:$B$23,0)) | N14: =IF(E14>0,INT(L14/E14),0) | O14: =IF(E14>0,INT(M14/E14),0)
A15: FG-003 | B15: =IFERROR(INDEX(품목_기준정보!$B$24:$B$35,MATCH(A15,품목_기준정보!$A$24:$A$35,0)),"") | C15: =IFERROR(INDEX(품목_기준정보!$C$6:$C$25,MATCH(D15,품목_기준정보!$B$6:$B$25,0)),"") | D15: 블랙오각선반 | E15: 1 | F15: EA | G15: 본체 (블랙 오각) | H15: =SUMIFS(생산_실적일지!$G$4:$G$100,생산_실적일지!$D$4:$D$100,A15) | I15: =E15*H15 | J15: =SUMIFS(재고현황_대시보드!$C$40:$C$45,재고현황_대시보드!$A$40:$A$45,A15) | K15: =E15*J15 | L15: =INDEX(재고현황_대시보드!$I$10:$I$23,MATCH(D15,재고현황_대시보드!$B$10:$B$23,0)) | M15: =INDEX(재고현황_대시보드!$K$10:$K$23,MATCH(D15,재고현황_대시보드!$B$10:$B$23,0)) | N15: =IF(E15>0,INT(L15/E15),0) | O15: =IF(E15>0,INT(M15/E15),0)
A16: FG-003 | B16: =IFERROR(INDEX(품목_기준정보!$B$24:$B$35,MATCH(A16,품목_기준정보!$A$24:$A$35,0)),"") | C16: =IFERROR(INDEX(품목_기준정보!$C$6:$C$25,MATCH(D16,품목_기준정보!$B$6:$B$25,0)),"") | D16: 블랙일자선반가이드 | E16: 1 | F16: EA | G16: 오각선반 가이드 1개 | H16: =SUMIFS(생산_실적일지!$G$4:$G$100,생산_실적일지!$D$4:$D$100,A16) | I16: =E16*H16 | J16: =SUMIFS(재고현황_대시보드!$C$40:$C$45,재고현황_대시보드!$A$40:$A$45,A16) | K16: =E16*J16 | L16: =INDEX(재고현황_대시보드!$I$10:$I$23,MATCH(D16,재고현황_대시보드!$B$10:$B$23,0)) | M16: =INDEX(재고현황_대시보드!$K$10:$K$23,MATCH(D16,재고현황_대시보드!$B$10:$B$23,0)) | N16: =IF(E16>0,INT(L16/E16),0) | O16: =IF(E16>0,INT(M16/E16),0)
... A34: FG-006 | B34: =IFERROR(INDEX(품목_기준정보!$B$24:$B$35,MATCH(A34,품목_기준정보!$A$24:$A$35,0)),"") | C34: =IFERROR(INDEX(품목_기준정보!$C$6:$C$25,MATCH(D34,품목_기준정보!$B$6:$B$25,0)),"") | D34: 칼브럭피스 | E34: 1 | F34: EA | G34: 벽면 고정 부속 세트 | H34: =SUMIFS(생산_실적일지!$G$4:$G$100,생산_실적일지!$D$4:$D$100,A34) | I34: =E34*H34 | J34: =SUMIFS(재고현황_대시보드!$C$40:$C$45,재고현황_대시보드!$A$40:$A$45,A34) | K34: =E34*J34 | L34: =INDEX(재고현황_대시보드!$I$10:$I$23,MATCH(D34,재고현황_대시보드!$B$10:$B$23,0)) | M34: =INDEX(재고현황_대시보드!$K$10:$K$23,MATCH(D34,재고현황_대시보드!$B$10:$B$23,0)) | N34: =IF(E34>0,INT(L34/E34),0) | O34: =IF(E34>0,INT(M34/E34),0)

Sheet 생산_실적일지
A1: 완제품 일일 생산 실적 일지
A2: ※ 사용자는 노란색 셀(일자, 전표, 라인, 코드, 생산/양품/불량수량, 작업자)만 입력합니다. 완제품명은 코드 기준 자동 표시됩니다.
A3: 일자 | B3: 생산전표번호 | C3: 생산라인 | D3: 완제품코드 | E3: 완제품명 | F3: 규격/구분 | G3: 생산수량(EA) | H3: 양품수량(EA) | I3: 불량수량(EA) | J3: 작업자/책임자 | K3: 검증상태 | L3: 비고
A4: 2026-09-17 | B4: PRD-2609-01 | C4: 조립 1라인 | D4: FG-001 | E4: =IF(D4="","",IFERROR(INDEX(품목_기준정보!$B$24:$B$35,MATCH(D4,품목_기준정보!$A$24:$A$35,0)),"미등록 완제품")) | F4: =IF(D4="","",IFERROR(INDEX(품목_기준정보!$C$24:$C$35,MATCH(D4,품목_기준정보!$A$24:$A$35,0)),"")) | G4: 300 | H4: 300 | I4: 0 | J4: 박조립 | K4: =IF(D4="","",IF(OR(G4<0,H4<0,I4<0),"음수 오류",IF(G4<>(H4+I4),"수량불일치 오류",IF(COUNTIF($B$4:$B$100,B4)>1,"중복 전표",IF(ISNA(MATCH(D4,품목_기준정보!$A$24:$A$35,0)),"미등록 완제품","정상"))))) | L4: 초도 양산 로트 완료
A5: 2026-09-18 | B5: PRD-2609-02 | C5: 조립 2라인 | D5: FG-004 | E5: =IF(D5="","",IFERROR(INDEX(품목_기준정보!$B$24:$B$35,MATCH(D5,품목_기준정보!$A$24:$A$35,0)),"미등록 완제품")) | F5: =IF(D5="","",IFERROR(INDEX(품목_기준정보!$C$24:$C$35,MATCH(D5,품목_기준정보!$A$24:$A$35,0)),"")) | G5: 500 | H5: 500 | I5: 0 | J5: 이조립 | K5: =IF(D5="","",IF(OR(G5<0,H5<0,I5<0),"음수 오류",IF(G5<>(H5+I5),"수량불일치 오류",IF(COUNTIF($B$4:$B$100,B5)>1,"중복 전표",IF(ISNA(MATCH(D5,품목_기준정보!$A$24:$A$35,0)),"미등록 완제품","정상"))))) | L5: 주간 정규 생산 물량
A6: 2026-09-18 | B6: PRD-2609-03 | C6: 조립 1라인 | D6: FG-003 | E6: =IF(D6="","",IFERROR(INDEX(품목_기준정보!$B$24:$B$35,MATCH(D6,품목_기준정보!$A$24:$A$35,0)),"미등록 완제품")) | F6: =IF(D6="","",IFERROR(INDEX(품목_기준정보!$C$24:$C$35,MATCH(D6,품목_기준정보!$A$24:$A$35,0)),"")) | G6: 100 | H6: 100 | I6: 0 | J6: 김조립 | K6: =IF(D6="","",IF(OR(G6<0,H6<0,I6<0),"음수 오류",IF(G6<>(H6+I6),"수량불일치 오류",IF(COUNTIF($B$4:$B$100,B6)>1,"중복 전표",IF(ISNA(MATCH(D6,품목_기준정보!$A$24:$A$35,0)),"미등록 완제품","정상"))))) | L6: 긴급 발주건 조립 완료
A7: 2026-09-19 | B7: SIM-PRD-001 | C7: 라인A | D7: FG-002 | E7: =IF(D7="","",IFERROR(INDEX(품목_기준정보!$B$24:$B$35,MATCH(D7,품목_기준정보!$A$24:$A$35,0)),"미등록 완제품")) | F7: =IF(D7="","",IFERROR(INDEX(품목_기준정보!$C$24:$C$35,MATCH(D7,품목_기준정보!$A$24:$A$35,0)),"")) | G7: 20 | H7: 20 | I7: 0 | J7: 시뮬 | K7: =IF(D7="","",IF(OR(G7<0,H7<0,I7<0),"음수 오류",IF(G7<>(H7+I7),"수량불일치 오류",IF(COUNTIF($B$4:$B$100,B7)>1,"중복 전표",IF(ISNA(MATCH(D7,품목_기준정보!$A$24:$A$35,0)),"미등록 완제품","정상"))))) | L7: 생산시뮬
E8: =IF(D8="","",IFERROR(INDEX(품목_기준정보!$B$24:$B$35,MATCH(D8,품목_기준정보!$A$24:$A$35,0)),"미등록 완제품")) | F8: =IF(D8="","",IFERROR(INDEX(품목_기준정보!$C$24:$C$35,MATCH(D8,품목_기준정보!$A$24:$A$35,0)),"")) | K8: =IF(D8="","",IF(OR(G8<0,H8<0,I8<0),"음수 오류",IF(G8<>(H8+I8),"수량불일치 오류",IF(COUNTIF($B$4:$B$100,B8)>1,"중복 전표",IF(ISNA(MATCH(D8,품목_기준정보!$A$24:$A$35,0)),"미등록 완제품","정상")))))
E9: =IF(D9="","",IFERROR(INDEX(품목_기준정보!$B$24:$B$35,MATCH(D9,품목_기준정보!$A$24:$A$35,0)),"미등록 완제품")) | F9: =IF(D9="","",IFERROR(INDEX(품목_기준정보!$C$24:$C$35,MATCH(D9,품목_기준정보!$A$24:$A$35,0)),"")) | K9: =IF(D9="","",IF(OR(G9<0,H9<0,I9<0),"음수 오류",IF(G9<>(H9+I9),"수량불일치 오류",IF(COUNTIF($B$4:$B$100,B9)>1,"중복 전표",IF(ISNA(MATCH(D9,품목_기준정보!$A$24:$A$35,0)),"미등록 완제품","정상")))))
E10: =IF(D10="","",IFERROR(INDEX(품목_기준정보!$B$24:$B$35,MATCH(D10,품목_기준정보!$A$24:$A$35,0)),"미등록 완제품")) | F10: =IF(D10="","",IFERROR(INDEX(품목_기준정보!$C$24:$C$35,MATCH(D10,품목_기준정보!$A$24:$A$35,0)),"")) | K10: =IF(D10="","",IF(OR(G10<0,H10<0,I10<0),"음수 오류",IF(G10<>(H10+I10),"수량불일치 오류",IF(COUNTIF($B$4:$B$100,B10)>1,"중복 전표",IF(ISNA(MATCH(D10,품목_기준정보!$A$24:$A$35,0)),"미등록 완제품","정상")))))
E11: =IF(D11="","",IFERROR(INDEX(품목_기준정보!$B$24:$B$35,MATCH(D11,품목_기준정보!$A$24:$A$35,0)),"미등록 완제품")) | F11: =IF(D11="","",IFERROR(INDEX(품목_기준정보!$C$24:$C$35,MATCH(D11,품목_기준정보!$A$24:$A$35,0)),"")) | K11: =IF(D11="","",IF(OR(G11<0,H11<0,I11<0),"음수 오류",IF(G11<>(H11+I11),"수량불일치 오류",IF(COUNTIF($B$4:$B$100,B11)>1,"중복 전표",IF(ISNA(MATCH(D11,품목_기준정보!$A$24:$A$35,0)),"미등록 완제품","정상")))))
E12: =IF(D12="","",IFERROR(INDEX(품목_기준정보!$B$24:$B$35,MATCH(D12,품목_기준정보!$A$24:$A$35,0)),"미등록 완제품")) | F12: =IF(D12="","",IFERROR(INDEX(품목_기준정보!$C$24:$C$35,MATCH(D12,품목_기준정보!$A$24:$A$35,0)),"")) | K12: =IF(D12="","",IF(OR(G12<0,H12<0,I12<0),"음수 오류",IF(G12<>(H12+I12),"수량불일치 오류",IF(COUNTIF($B$4:$B$100,B12)>1,"중복 전표",IF(ISNA(MATCH(D12,품목_기준정보!$A$24:$A$35,0)),"미등록 완제품","정상")))))
E13: =IF(D13="","",IFERROR(INDEX(품목_기준정보!$B$24:$B$35,MATCH(D13,품목_기준정보!$A$24:$A$35,0)),"미등록 완제품")) | F13: =IF(D13="","",IFERROR(INDEX(품목_기준정보!$C$24:$C$35,MATCH(D13,품목_기준정보!$A$24:$A$35,0)),"")) | K13: =IF(D13="","",IF(OR(G13<0,H13<0,I13<0),"음수 오류",IF(G13<>(H13+I13),"수량불일치 오류",IF(COUNTIF($B$4:$B$100,B13)>1,"중복 전표",IF(ISNA(MATCH(D13,품목_기준정보!$A$24:$A$35,0)),"미등록 완제품","정상")))))
E14: =IF(D14="","",IFERROR(INDEX(품목_기준정보!$B$24:$B$35,MATCH(D14,품목_기준정보!$A$24:$A$35,0)),"미등록 완제품")) | F14: =IF(D14="","",IFERROR(INDEX(품목_기준정보!$C$24:$C$35,MATCH(D14,품목_기준정보!$A$24:$A$35,0)),"")) | K14: =IF(D14="","",IF(OR(G14<0,H14<0,I14<0),"음수 오류",IF(G14<>(H14+I14),"수량불일치 오류",IF(COUNTIF($B$4:$B$100,B14)>1,"중복 전표",IF(ISNA(MATCH(D14,품목_기준정보!$A$24:$A$35,0)),"미등록 완제품","정상")))))
E15: =IF(D15="","",IFERROR(INDEX(품목_기준정보!$B$24:$B$35,MATCH(D15,품목_기준정보!$A$24:$A$35,0)),"미등록 완제품")) | F15: =IF(D15="","",IFERROR(INDEX(품목_기준정보!$C$24:$C$35,MATCH(D15,품목_기준정보!$A$24:$A$35,0)),"")) | K15: =IF(D15="","",IF(OR(G15<0,H15<0,I15<0),"음수 오류",IF(G15<>(H15+I15),"수량불일치 오류",IF(COUNTIF($B$4:$B$100,B15)>1,"중복 전표",IF(ISNA(MATCH(D15,품목_기준정보!$A$24:$A$35,0)),"미등록 완제품","정상")))))
E16: =IF(D16="","",IFERROR(INDEX(품목_기준정보!$B$24:$B$35,MATCH(D16,품목_기준정보!$A$24:$A$35,0)),"미등록 완제품")) | F16: =IF(D16="","",IFERROR(INDEX(품목_기준정보!$C$24:$C$35,MATCH(D16,품목_기준정보!$A$24:$A$35,0)),"")) | K16: =IF(D16="","",IF(OR(G16<0,H16<0,I16<0),"음수 오류",IF(G16<>(H16+I16),"수량불일치 오류",IF(COUNTIF($B$4:$B$100,B16)>1,"중복 전표",IF(ISNA(MATCH(D16,품목_기준정보!$A$24:$A$35,0)),"미등록 완제품","정상")))))
E17: =IF(D17="","",IFERROR(INDEX(품목_기준정보!$B$24:$B$35,MATCH(D17,품목_기준정보!$A$24:$A$35,0)),"미등록 완제품")) | F17: =IF(D17="","",IFERROR(INDEX(품목_기준정보!$C$24:$C$35,MATCH(D17,품목_기준정보!$A$24:$A$35,0)),"")) | K17: =IF(D17="","",IF(OR(G17<0,H17<0,I17<0),"음수 오류",IF(G17<>(H17+I17),"수량불일치 오류",IF(COUNTIF($B$4:$B$100,B17)>1,"중복 전표",IF(ISNA(MATCH(D17,품목_기준정보!$A$24:$A$35,0)),"미등록 완제품","정상")))))
E18: =IF(D18="","",IFERROR(INDEX(품목_기준정보!$B$24:$B$35,MATCH(D18,품목_기준정보!$A$24:$A$35,0)),"미등록 완제품")) | F18: =IF(D18="","",IFERROR(INDEX(품목_기준정보!$C$24:$C$35,MATCH(D18,품목_기준정보!$A$24:$A$35,0)),"")) | K18: =IF(D18="","",IF(OR(G18<0,H18<0,I18<0),"음수 오류",IF(G18<>(H18+I18),"수량불일치 오류",IF(COUNTIF($B$4:$B$100,B18)>1,"중복 전표",IF(ISNA(MATCH(D18,품목_기준정보!$A$24:$A$35,0)),"미등록 완제품","정상")))))
E19: =IF(D19="","",IFERROR(INDEX(품목_기준정보!$B$24:$B$35,MATCH(D19,품목_기준정보!$A$24:$A$35,0)),"미등록 완제품")) | F19: =IF(D19="","",IFERROR(INDEX(품목_기준정보!$C$24:$C$35,MATCH(D19,품목_기준정보!$A$24:$A$35,0)),"")) | K19: =IF(D19="","",IF(OR(G19<0,H19<0,I19<0),"음수 오류",IF(G19<>(H19+I19),"수량불일치 오류",IF(COUNTIF($B$4:$B$100,B19)>1,"중복 전표",IF(ISNA(MATCH(D19,품목_기준정보!$A$24:$A$35,0)),"미등록 완제품","정상")))))
... E100: =IF(D100="","",IFERROR(INDEX(품목_기준정보!$B$24:$B$35,MATCH(D100,품목_기준정보!$A$24:$A$35,0)),"미등록 완제품")) | F100: =IF(D100="","",IFERROR(INDEX(품목_기준정보!$C$24:$C$35,MATCH(D100,품목_기준정보!$A$24:$A$35,0)),"")) | K100: =IF(D100="","",IF(OR(G100<0,H100<0,I100<0),"음수 오류",IF(G100<>(H100+I100),"수량불일치 오류",IF(COUNTIF($B$4:$B$100,B100)>1,"중복 전표",IF(ISNA(MATCH(D100,품목_기준정보!$A$24:$A$35,0)),"미등록 완제품","정상")))))

Sheet 자재_입출고원장
A1: 원부자재 입출고 수불 원장
A2: ※ 신규 자재 입고 및 기타 출고(폐기/반출/실사조정)를 기록합니다. 생산 투입은 생산실적일지에서 자동 차감됩니다.
A3: 일자 | B3: 전표번호 | C3: 구분 | D3: 부품구분 | E3: 부품명 | F3: 단위 | G3: 입고수량 | H3: 기타출고수량 | I3: 거래처/적요 | J3: 비고/상세사유 | K3: 담당자 | L3: 검증상태
A4: 2026-09-15 | B4: IN-2609-01 | C4: 입고 | D4: =IF(E4="","",IFERROR(INDEX(품목_기준정보!$C$6:$C$25,MATCH(E4,품목_기준정보!$B$6:$B$25,0)),"미등록 품목")) | E4: 크롬일자선반가이드 | F4: =IF(E4="","",IFERROR(INDEX(품목_기준정보!$D$6:$D$25,MATCH(E4,품목_기준정보!$B$6:$B$25,0)),"")) | G4: 100 | H4: 0 | I4: (주)메탈테크 | J4: 신규 라인 시운전용 입고 | K4: 김자재 | L4: =IF(E4="","",IF(OR(G4<0,H4<0),"음수 오류",IF(ISNA(MATCH(E4,품목_기준정보!$B$6:$B$25,0)),"미등록 품목",IF(COUNTIF($B$4:$B$100,B4)>1,"중복 전표","정상"))))
A5: 2026-09-16 | B5: IN-2609-02 | C5: 입고 | D5: =IF(E5="","",IFERROR(INDEX(품목_기준정보!$C$6:$C$25,MATCH(E5,품목_기준정보!$B$6:$B$25,0)),"미등록 품목")) | E5: 블랙일자선반가이드 | F5: =IF(E5="","",IFERROR(INDEX(품목_기준정보!$D$6:$D$25,MATCH(E5,품목_기준정보!$B$6:$B$25,0)),"")) | G5: 200 | H5: 0 | I5: (주)메탈테크 | J5: 부족 부품 보충 입고 | K5: 김자재 | L5: =IF(E5="","",IF(OR(G5<0,H5<0),"음수 오류",IF(ISNA(MATCH(E5,품목_기준정보!$B$6:$B$25,0)),"미등록 품목",IF(COUNTIF($B$4:$B$100,B5)>1,"중복 전표","정상"))))
A6: 2026-09-17 | B6: OUT-2609-01 | C6: 출고 | D6: =IF(E6="","",IFERROR(INDEX(품목_기준정보!$C$6:$C$25,MATCH(E6,품목_기준정보!$B$6:$B$25,0)),"미등록 품목")) | E6: 블랙삼각선반 | F6: =IF(E6="","",IFERROR(INDEX(품목_기준정보!$D$6:$D$25,MATCH(E6,품목_기준정보!$B$6:$B$25,0)),"")) | G6: 0 | H6: 5 | I6: 품질관리팀 | J6: 운반 중 파손 폐기 처리 | K6: 이품질 | L6: =IF(E6="","",IF(OR(G6<0,H6<0),"음수 오류",IF(ISNA(MATCH(E6,품목_기준정보!$B$6:$B$25,0)),"미등록 품목",IF(COUNTIF($B$4:$B$100,B6)>1,"중복 전표","정상"))))
A7: 2026-09-18 | B7: IN-2609-03 | C7: 입고 | D7: =IF(E7="","",IFERROR(INDEX(품목_기준정보!$C$6:$C$25,MATCH(E7,품목_기준정보!$B$6:$B$25,0)),"미등록 품목")) | E7: 비닐 | F7: =IF(E7="","",IFERROR(INDEX(품목_기준정보!$D$6:$D$25,MATCH(E7,품목_기준정보!$B$6:$B$25,0)),"")) | G7: 500 | H7: 0 | I7: (주)화스너테크 | J7: 정기 안전재고 보충 | K7: 김자재 | L7: =IF(E7="","",IF(OR(G7<0,H7<0),"음수 오류",IF(ISNA(MATCH(E7,품목_기준정보!$B$6:$B$25,0)),"미등록 품목",IF(COUNTIF($B$4:$B$100,B7)>1,"중복 전표","정상"))))
D8: =IF(E8="","",IFERROR(INDEX(품목_기준정보!$C$6:$C$25,MATCH(E8,품목_기준정보!$B$6:$B$25,0)),"미등록 품목")) | F8: =IF(E8="","",IFERROR(INDEX(품목_기준정보!$D$6:$D$25,MATCH(E8,품목_기준정보!$B$6:$B$25,0)),"")) | L8: =IF(E8="","",IF(OR(G8<0,H8<0),"음수 오류",IF(ISNA(MATCH(E8,품목_기준정보!$B$6:$B$25,0)),"미등록 품목",IF(COUNTIF($B$4:$B$100,B8)>1,"중복 전표","정상"))))
D9: =IF(E9="","",IFERROR(INDEX(품목_기준정보!$C$6:$C$25,MATCH(E9,품목_기준정보!$B$6:$B$25,0)),"미등록 품목")) | F9: =IF(E9="","",IFERROR(INDEX(품목_기준정보!$D$6:$D$25,MATCH(E9,품목_기준정보!$B$6:$B$25,0)),"")) | L9: =IF(E9="","",IF(OR(G9<0,H9<0),"음수 오류",IF(ISNA(MATCH(E9,품목_기준정보!$B$6:$B$25,0)),"미등록 품목",IF(COUNTIF($B$4:$B$100,B9)>1,"중복 전표","정상"))))
D10: =IF(E10="","",IFERROR(INDEX(품목_기준정보!$C$6:$C$25,MATCH(E10,품목_기준정보!$B$6:$B$25,0)),"미등록 품목")) | F10: =IF(E10="","",IFERROR(INDEX(품목_기준정보!$D$6:$D$25,MATCH(E10,품목_기준정보!$B$6:$B$25,0)),"")) | L10: =IF(E10="","",IF(OR(G10<0,H10<0),"음수 오류",IF(ISNA(MATCH(E10,품목_기준정보!$B$6:$B$25,0)),"미등록 품목",IF(COUNTIF($B$4:$B$100,B10)>1,"중복 전표","정상"))))
D11: =IF(E11="","",IFERROR(INDEX(품목_기준정보!$C$6:$C$25,MATCH(E11,품목_기준정보!$B$6:$B$25,0)),"미등록 품목")) | F11: =IF(E11="","",IFERROR(INDEX(품목_기준정보!$D$6:$D$25,MATCH(E11,품목_기준정보!$B$6:$B$25,0)),"")) | L11: =IF(E11="","",IF(OR(G11<0,H11<0),"음수 오류",IF(ISNA(MATCH(E11,품목_기준정보!$B$6:$B$25,0)),"미등록 품목",IF(COUNTIF($B$4:$B$100,B11)>1,"중복 전표","정상"))))
D12: =IF(E12="","",IFERROR(INDEX(품목_기준정보!$C$6:$C$25,MATCH(E12,품목_기준정보!$B$6:$B$25,0)),"미등록 품목")) | F12: =IF(E12="","",IFERROR(INDEX(품목_기준정보!$D$6:$D$25,MATCH(E12,품목_기준정보!$B$6:$B$25,0)),"")) | L12: =IF(E12="","",IF(OR(G12<0,H12<0),"음수 오류",IF(ISNA(MATCH(E12,품목_기준정보!$B$6:$B$25,0)),"미등록 품목",IF(COUNTIF($B$4:$B$100,B12)>1,"중복 전표","정상"))))
D13: =IF(E13="","",IFERROR(INDEX(품목_기준정보!$C$6:$C$25,MATCH(E13,품목_기준정보!$B$6:$B$25,0)),"미등록 품목")) | F13: =IF(E13="","",IFERROR(INDEX(품목_기준정보!$D$6:$D$25,MATCH(E13,품목_기준정보!$B$6:$B$25,0)),"")) | L13: =IF(E13="","",IF(OR(G13<0,H13<0),"음수 오류",IF(ISNA(MATCH(E13,품목_기준정보!$B$6:$B$25,0)),"미등록 품목",IF(COUNTIF($B$4:$B$100,B13)>1,"중복 전표","정상"))))
D14: =IF(E14="","",IFERROR(INDEX(품목_기준정보!$C$6:$C$25,MATCH(E14,품목_기준정보!$B$6:$B$25,0)),"미등록 품목")) | F14: =IF(E14="","",IFERROR(INDEX(품목_기준정보!$D$6:$D$25,MATCH(E14,품목_기준정보!$B$6:$B$25,0)),"")) | L14: =IF(E14="","",IF(OR(G14<0,H14<0),"음수 오류",IF(ISNA(MATCH(E14,품목_기준정보!$B$6:$B$25,0)),"미등록 품목",IF(COUNTIF($B$4:$B$100,B14)>1,"중복 전표","정상"))))
D15: =IF(E15="","",IFERROR(INDEX(품목_기준정보!$C$6:$C$25,MATCH(E15,품목_기준정보!$B$6:$B$25,0)),"미등록 품목")) | F15: =IF(E15="","",IFERROR(INDEX(품목_기준정보!$D$6:$D$25,MATCH(E15,품목_기준정보!$B$6:$B$25,0)),"")) | L15: =IF(E15="","",IF(OR(G15<0,H15<0),"음수 오류",IF(ISNA(MATCH(E15,품목_기준정보!$B$6:$B$25,0)),"미등록 품목",IF(COUNTIF($B$4:$B$100,B15)>1,"중복 전표","정상"))))
D16: =IF(E16="","",IFERROR(INDEX(품목_기준정보!$C$6:$C$25,MATCH(E16,품목_기준정보!$B$6:$B$25,0)),"미등록 품목")) | F16: =IF(E16="","",IFERROR(INDEX(품목_기준정보!$D$6:$D$25,MATCH(E16,품목_기준정보!$B$6:$B$25,0)),"")) | L16: =IF(E16="","",IF(OR(G16<0,H16<0),"음수 오류",IF(ISNA(MATCH(E16,품목_기준정보!$B$6:$B$25,0)),"미등록 품목",IF(COUNTIF($B$4:$B$100,B16)>1,"중복 전표","정상"))))
D17: =IF(E17="","",IFERROR(INDEX(품목_기준정보!$C$6:$C$25,MATCH(E17,품목_기준정보!$B$6:$B$25,0)),"미등록 품목")) | F17: =IF(E17="","",IFERROR(INDEX(품목_기준정보!$D$6:$D$25,MATCH(E17,품목_기준정보!$B$6:$B$25,0)),"")) | L17: =IF(E17="","",IF(OR(G17<0,H17<0),"음수 오류",IF(ISNA(MATCH(E17,품목_기준정보!$B$6:$B$25,0)),"미등록 품목",IF(COUNTIF($B$4:$B$100,B17)>1,"중복 전표","정상"))))
D18: =IF(E18="","",IFERROR(INDEX(품목_기준정보!$C$6:$C$25,MATCH(E18,품목_기준정보!$B$6:$B$25,0)),"미등록 품목")) | F18: =IF(E18="","",IFERROR(INDEX(품목_기준정보!$D$6:$D$25,MATCH(E18,품목_기준정보!$B$6:$B$25,0)),"")) | L18: =IF(E18="","",IF(OR(G18<0,H18<0),"음수 오류",IF(ISNA(MATCH(E18,품목_기준정보!$B$6:$B$25,0)),"미등록 품목",IF(COUNTIF($B$4:$B$100,B18)>1,"중복 전표","정상"))))
D19: =IF(E19="","",IFERROR(INDEX(품목_기준정보!$C$6:$C$25,MATCH(E19,품목_기준정보!$B$6:$B$25,0)),"미등록 품목")) | F19: =IF(E19="","",IFERROR(INDEX(품목_기준정보!$D$6:$D$25,MATCH(E19,품목_기준정보!$B$6:$B$25,0)),"")) | L19: =IF(E19="","",IF(OR(G19<0,H19<0),"음수 오류",IF(ISNA(MATCH(E19,품목_기준정보!$B$6:$B$25,0)),"미등록 품목",IF(COUNTIF($B$4:$B$100,B19)>1,"중복 전표","정상"))))
... D100: =IF(E100="","",IFERROR(INDEX(품목_기준정보!$C$6:$C$25,MATCH(E100,품목_기준정보!$B$6:$B$25,0)),"미등록 품목")) | F100: =IF(E100="","",IFERROR(INDEX(품목_기준정보!$D$6:$D$25,MATCH(E100,품목_기준정보!$B$6:$B$25,0)),"")) | L100: =IF(E100="","",IF(OR(G100<0,H100<0),"음수 오류",IF(ISNA(MATCH(E100,품목_기준정보!$B$6:$B$25,0)),"미등록 품목",IF(COUNTIF($B$4:$B$100,B100)>1,"중복 전표","정상"))))

Sheet 발주_미입고관리
A1: 원부자재 발주 및 미입고 관리 대장
A2: ※ 발주 내역 및 입고 진행 상황을 등록합니다. 미입고 잔량은 대시보드의 가용재고 및 필요발주량 계산에 자동 반영됩니다.
A3: 발주일 | B3: 발주번호 | C3: 부품코드 | D3: 부품명 | E3: 단위 | F3: 발주수량 | G3: 입고완료수량 | H3: 미입고수량 | I3: 예정입고일 | J3: 거래처 | K3: 상태 | L3: 비고
A4: 2026-09-18 | B4: PO-2609-01 | C4: =IF(D4="","",IFERROR(INDEX(품목_기준정보!$A$6:$A$25,MATCH(D4,품목_기준정보!$B$6:$B$25,0)),"")) | D4: 블랙삼각선반 | E4: =IF(D4="","",IFERROR(INDEX(품목_기준정보!$D$6:$D$25,MATCH(D4,품목_기준정보!$B$6:$B$25,0)),"")) | F4: 30 | G4: 0 | H4: =IF(F4="","",MAX(F4-G4,0)) | I4: 2026-09-22 | J4: (주)대한유리 | K4: =IF(F4="","-",IF(G4>=F4,"입고완료",IF(G4>0,"부분입고","미입고"))) | L4: 안전재고 주의 부품 긴급 발주
A5: 2026-09-18 | B5: TEST-PO-001 | C5: =IF(D5="","",IFERROR(INDEX(품목_기준정보!$A$6:$A$25,MATCH(D5,품목_기준정보!$B$6:$B$25,0)),"")) | D5: 칼브럭피스 | E5: =IF(D5="","",IFERROR(INDEX(품목_기준정보!$D$6:$D$25,MATCH(D5,품목_기준정보!$B$6:$B$25,0)),"")) | F5: 1000 | G5: 0 | H5: =IF(F5="","",MAX(F5-G5,0)) | I5: 2026-09-25 | J5: 테스트업체 | K5: =IF(F5="","-",IF(G5>=F5,"입고완료",IF(G5>0,"부분입고","미입고"))) | L5: 발주테스트
A6: 2026-09-19 | B6: BATCH-RM-GL-01 | C6: =IF(D6="","",IFERROR(INDEX(품목_기준정보!$A$6:$A$25,MATCH(D6,품목_기준정보!$B$6:$B$25,0)),"")) | D6: 블랙삼각선반 | E6: =IF(D6="","",IFERROR(INDEX(품목_기준정보!$D$6:$D$25,MATCH(D6,품목_기준정보!$B$6:$B$25,0)),"")) | F6: 100 | G6: 0 | H6: =IF(F6="","",MAX(F6-G6,0)) | I6: 2026-09-30 | J6: 자동발주 | K6: =IF(F6="","-",IF(G6>=F6,"입고완료",IF(G6>0,"부분입고","미입고"))) | L6: 테스트
A7: 2026-09-19 | B7: BATCH-RM-GL-04 | C7: =IF(D7="","",IFERROR(INDEX(품목_기준정보!$A$6:$A$25,MATCH(D7,품목_기준정보!$B$6:$B$25,0)),"")) | D7: 그린삼각선반 | E7: =IF(D7="","",IFERROR(INDEX(품목_기준정보!$D$6:$D$25,MATCH(D7,품목_기준정보!$B$6:$B$25,0)),"")) | F7: 75 | G7: 0 | H7: =IF(F7="","",MAX(F7-G7,0)) | I7: 2026-09-30 | J7: 자동발주 | K7: =IF(F7="","-",IF(G7>=F7,"입고완료",IF(G7>0,"부분입고","미입고"))) | L7: 테스트
A8: 2026-09-19 | B8: BATCH-RM-GD-02 | C8: =IF(D8="","",IFERROR(INDEX(품목_기준정보!$A$6:$A$25,MATCH(D8,품목_기준정보!$B$6:$B$25,0)),"")) | D8: 블랙일자선반가이드 | E8: =IF(D8="","",IFERROR(INDEX(품목_기준정보!$D$6:$D$25,MATCH(D8,품목_기준정보!$B$6:$B$25,0)),"")) | F8: 40 | G8: 0 | H8: =IF(F8="","",MAX(F8-G8,0)) | I8: 2026-09-30 | J8: 자동발주 | K8: =IF(F8="","-",IF(G8>=F8,"입고완료",IF(G8>0,"부분입고","미입고"))) | L8: 테스트
C9: =IF(D9="","",IFERROR(INDEX(품목_기준정보!$A$6:$A$25,MATCH(D9,품목_기준정보!$B$6:$B$25,0)),"")) | E9: =IF(D9="","",IFERROR(INDEX(품목_기준정보!$D$6:$D$25,MATCH(D9,품목_기준정보!$B$6:$B$25,0)),"")) | H9: =IF(F9="","",MAX(F9-G9,0)) | K9: =IF(F9="","-",IF(G9>=F9,"입고완료",IF(G9>0,"부분입고","미입고")))
C10: =IF(D10="","",IFERROR(INDEX(품목_기준정보!$A$6:$A$25,MATCH(D10,품목_기준정보!$B$6:$B$25,0)),"")) | E10: =IF(D10="","",IFERROR(INDEX(품목_기준정보!$D$6:$D$25,MATCH(D10,품목_기준정보!$B$6:$B$25,0)),"")) | H10: =IF(F10="","",MAX(F10-G10,0)) | K10: =IF(F10="","-",IF(G10>=F10,"입고완료",IF(G10>0,"부분입고","미입고")))
C11: =IF(D11="","",IFERROR(INDEX(품목_기준정보!$A$6:$A$25,MATCH(D11,품목_기준정보!$B$6:$B$25,0)),"")) | E11: =IF(D11="","",IFERROR(INDEX(품목_기준정보!$D$6:$D$25,MATCH(D11,품목_기준정보!$B$6:$B$25,0)),"")) | H11: =IF(F11="","",MAX(F11-G11,0)) | K11: =IF(F11="","-",IF(G11>=F11,"입고완료",IF(G11>0,"부분입고","미입고")))
C12: =IF(D12="","",IFERROR(INDEX(품목_기준정보!$A$6:$A$25,MATCH(D12,품목_기준정보!$B$6:$B$25,0)),"")) | E12: =IF(D12="","",IFERROR(INDEX(품목_기준정보!$D$6:$D$25,MATCH(D12,품목_기준정보!$B$6:$B$25,0)),"")) | H12: =IF(F12="","",MAX(F12-G12,0)) | K12: =IF(F12="","-",IF(G12>=F12,"입고완료",IF(G12>0,"부분입고","미입고")))
C13: =IF(D13="","",IFERROR(INDEX(품목_기준정보!$A$6:$A$25,MATCH(D13,품목_기준정보!$B$6:$B$25,0)),"")) | E13: =IF(D13="","",IFERROR(INDEX(품목_기준정보!$D$6:$D$25,MATCH(D13,품목_기준정보!$B$6:$B$25,0)),"")) | H13: =IF(F13="","",MAX(F13-G13,0)) | K13: =IF(F13="","-",IF(G13>=F13,"입고완료",IF(G13>0,"부분입고","미입고")))
C14: =IF(D14="","",IFERROR(INDEX(품목_기준정보!$A$6:$A$25,MATCH(D14,품목_기준정보!$B$6:$B$25,0)),"")) | E14: =IF(D14="","",IFERROR(INDEX(품목_기준정보!$D$6:$D$25,MATCH(D14,품목_기준정보!$B$6:$B$25,0)),"")) | H14: =IF(F14="","",MAX(F14-G14,0)) | K14: =IF(F14="","-",IF(G14>=F14,"입고완료",IF(G14>0,"부분입고","미입고")))
C15: =IF(D15="","",IFERROR(INDEX(품목_기준정보!$A$6:$A$25,MATCH(D15,품목_기준정보!$B$6:$B$25,0)),"")) | E15: =IF(D15="","",IFERROR(INDEX(품목_기준정보!$D$6:$D$25,MATCH(D15,품목_기준정보!$B$6:$B$25,0)),"")) | H15: =IF(F15="","",MAX(F15-G15,0)) | K15: =IF(F15="","-",IF(G15>=F15,"입고완료",IF(G15>0,"부분입고","미입고")))
C16: =IF(D16="","",IFERROR(INDEX(품목_기준정보!$A$6:$A$25,MATCH(D16,품목_기준정보!$B$6:$B$25,0)),"")) | E16: =IF(D16="","",IFERROR(INDEX(품목_기준정보!$D$6:$D$25,MATCH(D16,품목_기준정보!$B$6:$B$25,0)),"")) | H16: =IF(F16="","",MAX(F16-G16,0)) | K16: =IF(F16="","-",IF(G16>=F16,"입고완료",IF(G16>0,"부분입고","미입고")))
C17: =IF(D17="","",IFERROR(INDEX(품목_기준정보!$A$6:$A$25,MATCH(D17,품목_기준정보!$B$6:$B$25,0)),"")) | E17: =IF(D17="","",IFERROR(INDEX(품목_기준정보!$D$6:$D$25,MATCH(D17,품목_기준정보!$B$6:$B$25,0)),"")) | H17: =IF(F17="","",MAX(F17-G17,0)) | K17: =IF(F17="","-",IF(G17>=F17,"입고완료",IF(G17>0,"부분입고","미입고")))
C18: =IF(D18="","",IFERROR(INDEX(품목_기준정보!$A$6:$A$25,MATCH(D18,품목_기준정보!$B$6:$B$25,0)),"")) | E18: =IF(D18="","",IFERROR(INDEX(품목_기준정보!$D$6:$D$25,MATCH(D18,품목_기준정보!$B$6:$B$25,0)),"")) | H18: =IF(F18="","",MAX(F18-G18,0)) | K18: =IF(F18="","-",IF(G18>=F18,"입고완료",IF(G18>0,"부분입고","미입고")))
C19: =IF(D19="","",IFERROR(INDEX(품목_기준정보!$A$6:$A$25,MATCH(D19,품목_기준정보!$B$6:$B$25,0)),"")) | E19: =IF(D19="","",IFERROR(INDEX(품목_기준정보!$D$6:$D$25,MATCH(D19,품목_기준정보!$B$6:$B$25,0)),"")) | H19: =IF(F19="","",MAX(F19-G19,0)) | K19: =IF(F19="","-",IF(G19>=F19,"입고완료",IF(G19>0,"부분입고","미입고")))
C20: =IF(D20="","",IFERROR(INDEX(품목_기준정보!$A$6:$A$25,MATCH(D20,품목_기준정보!$B$6:$B$25,0)),"")) | E20: =IF(D20="","",IFERROR(INDEX(품목_기준정보!$D$6:$D$25,MATCH(D20,품목_기준정보!$B$6:$B$25,0)),"")) | H20: =IF(F20="","",MAX(F20-G20,0)) | K20: =IF(F20="","-",IF(G20>=F20,"입고완료",IF(G20>0,"부분입고","미입고")))
... C100: =IF(D100="","",IFERROR(INDEX(품목_기준정보!$A$6:$A$25,MATCH(D100,품목_기준정보!$B$6:$B$25,0)),"")) | E100: =IF(D100="","",IFERROR(INDEX(품목_기준정보!$D$6:$D$25,MATCH(D100,품목_기준정보!$B$6:$B$25,0)),"")) | H100: =IF(F100="","",MAX(F100-G100,0)) | K100: =IF(F100="","-",IF(G100>=F100,"입고완료",IF(G100>0,"부분입고","미입고")))

Sheet 사용_설명서
A1: 📘 원부자재 재고·생산·BOM·발주 관리 MRP 시스템 사용 설명서 (SOP & Manual)
A2: ※ 본 시스템은 BOM을 단일 기준정보로 하여 생산실적 및 입출고에 따른 실시간 자재 자동 차감(백플러시)과 MRP 기능을 제공합니다.
A4: 【 1. 시스템 초기 설정 및 일상 운영 흐름 (표준 운영 7단계) 】
A5: 단계 | B5: 업무명 | C5: 관련 시트 | D5: 주요 작업 내용 및 세부 수칙 | E5: 자동 반영 및 연계 결과
A6: STEP 1 | B6: 품목 기준정보 확인 | C6: 품목_기준정보 | D6: 부품코드, 부품명, 기초재고, 안전재고, 목표재고를 확인하고 신규 부품 필요 시 행을 등록합니다. | E6: 대시보드 수불 현황의 품목 및 안전재고 기준으로 자동 연계
A7: STEP 2 | B7: BOM 정규형 등록 | C7: BOM_정규형 | D7: 완제품 1개 생산 시 소요되는 부품명과 소요원단위(EA)를 등록합니다. | E7: 모든 생산차감, 생산계획 소요량, 가용 생산능력의 단일 기준으로 작동
A8: STEP 3 | B8: 자재 입고/출고 등록 | C8: 자재_입출고원장 | D8: 협력업체 입고 발생 시 '입고'로, 폐기/파손/샘플 반출 시 '출고'로 전표 및 수량을 입력합니다. | E8: 대시보드의 '입고누계', '기타출고' 및 현재고에 실시간 합산
A9: STEP 4 | B9: 완제품 생산실적 등록 | C9: 생산_실적일지 | D9: 조립 완료 시 일자, 전표, 라인, 완제품코드, 생산수량, 양품/불량수량을 등록합니다. | E9: BOM 소요원단위에 따라 모든 원부자재가 실시간 자동 차감(백플러시)
A10: STEP 5 | B10: 발주 및 미입고 등록 | C10: 발주_미입고관리 | D10: 원부자재 발주 시 발주일, 발주번호, 부품명, 발주수량을 등록하고 입고 시 완료수량을 입력합니다. | E10: 미입고잔량이 대시보드의 '미입고예정량' 및 '가용재고'에 즉시 가산
A11: STEP 6 | B11: 생산계획 시뮬레이션 | C11: 재고현황_대시보드 | D11: 생산 계획 수량을 입력하면 현재고 기준 가능 여부 및 부품별 계획 총소요량을 자동 계산합니다. | E11: 부품별 예상 잔여재고 및 과부족 발생 시 추가 발주 필요량 자동 산출
A12: STEP 7 | B12: 대시보드 점검 & 발주 | C12: 재고현황_대시보드 | D12: KPI 스코어카드(부족/주의 알림)와 필요발주량을 확인하고 구매팀에 발주를 진행합니다. | E12: 자재 결품으로 인한 라인 정지 사전 방지 및 적정 재고 유지
A15: 【 2. 신제품(완제품) 추가 시 표준 절차 (대시보드 수식 수정 0건 원칙) 】
A16: 순서 | B16: 구분 | C16: 작업 시트 | D16: 상세 작업 절차 | E16: 비고 및 주의사항
A17: 1단계 | B17: 완제품코드 등록 | C17: 품목_기준정보 | D17: 하단 '완제품 기준정보 마스터'에 신규 완제품코드(예: FG-007), 완제품명, 규격을 추가합니다. | E17: 완제품코드는 중복되지 않는 고유 코드로 채번
A18: 2단계 | B18: BOM에 부품 구성 추가 | C18: BOM_정규형 | D18: 신규 완제품을 구성하는 부품들과 소요원단위(EA)를 'BOM_정규형' 하단에 행으로 추가합니다. | E18: 부품명은 품목_기준정보의 부품명과 100% 동일하게 입력
A19: 3단계 | B19: 신규 부품 등록 (필요시) | C19: 품목_기준정보 | D19: 기존에 없던 새로운 부품이 쓰인다면 '원부자재 기준정보 마스터'에 부품코드/부품명을 먼저 등록합니다. | E19: 대시보드 수불 현황에도 행을 추가하여 재고 관리
A20: 4단계 | B20: 생산실적 입력 | C20: 생산_실적일지 | D20: 생산실적에 신규 완제품코드(FG-007)와 생산수량을 입력합니다. | E20: 완제품명과 규격이 자동 조회되며 입력 완료
A21: 완료! | B21: 자동 연동 확인 | C21: 재고현황_대시보드 | D21: 대시보드 수식을 전혀 수정하지 않아도 BOM에 등록된 부품들의 생산차감과 재고가 자동 반영됩니다. | E21: ★ 수식 하드코딩 0% 구조로 100% 자동화 달성
A24: 【 3. 셀 배경 색상 구분 규칙 (사용자 안내) 】
A25: 색상 구분 | B25: 표시 색상 예시 | C25: 해당 셀 영역 | D25: 작업 지침
A26: 사용자 수기 입력 셀 | B26: ■ SAMPLE | C26: 일자, 전표번호, 코드, 실적/계획수량, 거래처 등 | D26: 사용자가 직접 타이핑하거나 선택하여 입력하는 영역입니다.
A27: 시스템 자동 계산 셀 | B27: ■ SAMPLE | C27: 생산차감, 현재고, 가용재고, 최대가능량, 발주량 등 | D27: 수식이 적용되어 있으므로 임의로 수정하거나 삭제하지 마십시오.
A28: 오류 및 경고 알림 셀 | B28: ■ SAMPLE | C28: 수량불일치 오류, 음수 오류, 미등록 품목, 재고 부족 | D28: 입력 데이터에 오류가 있거나 재고가 결품 상태이므로 확인 조치하십시오.
A31: 【 4. 자주 묻는 질문 및 현장 트러블슈팅 가이드 (FAQ) 】
A32: 구분 | B32: 질문 및 상황 | C32: 원인 분석 | D32: 표준 조치 방법
A33: Q1 | B33: 실제 재고와 장부상 현재고가 맞지 않음 | C33: 미기록 출고, 공정 불량 부품 미기록, 자재 파손 누락 | D33: 실물 수량을 파악한 후 '자재_입출고원장'에 차이 수량을 '출고'(비고: 재고실사조정)로 등록
A34: Q2 | B34: 생산실적을 넣었는데 자재 차감이 안 됨 | C34: 완제품코드 오입력 또는 BOM 정규형에 해당 완제품/부품 누락 | D34: '생산_실적일지' 완제품코드 철자 확인 및 'BOM_정규형' 매칭 점검
A35: Q3 | B35: 생산실적 검증상태에 '수량불일치 오류' | C35: 생산수량 ≠ 양품수량 + 불량수량 불일치 | D35: 생산수량과 양품+불량의 합계가 일치하도록 수량 정정
A36: Q4 | B36: 완제품 생산가능량이 0으로 표시됨 | C36: 해당 완제품을 구성하는 부품 중 1개 이상이 현재고 결품(병목) | D36: 대시보드의 '병목부품' 열을 확인하여 부족한 부품 긴급 발주 진행

Sheet BOM_매트릭스(참고용)
A1: 완제품별 부품 소요 매트릭스 (참고용 뷰)
A2: ※ 기존 파일의 매트릭스 형태를 보존한 참고용 시트입니다. 시스템의 모든 연산은 'BOM_정규형'을 기준으로 작동합니다.
A4: 완제품 코드 | B4: 완제품명 | C4: 구분 | D4: 유리선반 | E4: 유리 소요량 | F4: 선반가이드 | G4: 가이드 소요량 | H4: 선반브라켓 | I4: 브라켓 소요량
A5: FG-001 | B5: 블랙코너선반 | C5: 블랙 / 삼각 | D5: 블랙삼각선반 | E5: 1 | F5: 블랙코너선반가이드 | G5: 1 | H5: 블랙선반브라켓 | I5: 2
A6: FG-002 | B6: 블랙일자선반 | C6: 블랙 / 일자 | D6: 블랙일자선반 | E6: 1 | F6: 블랙일자선반가이드 | G6: 2 | H6: 블랙선반브라켓 | I6: 2
A7: FG-003 | B7: 블랙오각선반 | C7: 블랙 / 오각 | D7: 블랙오각선반 | E7: 1 | F7: 블랙일자선반가이드 | G7: 1 | H7: 블랙선반브라켓 | I7: 2
A8: FG-004 | B8: 코너선반 | C8: 그린 / 삼각 | D8: 그린삼각선반 | E8: 1 | F8: 크롬코너선반가이드 | G8: 1 | H8: 크롬선반브라켓 | I8: 2
A9: FG-005 | B9: 일자선반 | C9: 그린 / 일자 | D9: 그린일자선반 | E9: 1 | F9: 크롬일자선반가이드 | G9: 2 | H9: 크롬선반브라켓 | I9: 2
A10: FG-006 | B10: 오각선반 | C10: 그린 / 오각 | D10: 그린오각선반 | E10: 1 | F10: 크롬일자선반가이드 | G10: 1 | H10: 크롬선반브라켓 | I10: 2

Sheet 기존_참고자료
B3: 품목 | C3: 구분 | D3: 규격 | E3: 묶음수량 | F3: 수량 | G3: 비고
B4: 박스 | C4: 일자선반 | D4: 인박스 | F4: OK
C5: 일자선반 | D5: 카튼박스 | F5: OK
C6: 코너선반 | D6: 인박스 | F6: X
C7: 코너선반 | D7: 카튼박스 | F7: 100
B8: 유리선반 | C8: 블랙 | D8: 오각 | E8: 46 BOX | F8: 1150 | G8: 25 개입/1BOX
D9: 삼각(라운드) | E9: 13 BOX | F9: 325 | G9: 25 개입/1BOX
D10: 일자 | E10: 10 BOX | F10: 200 | G10: 20 개입/1BOX
C11: 그린 | D11: 오각 | E11: 34 BOX | F11: 850 | G11: 25 개입/1BOX
D12: 삼각(라운드) | E12: 21 BOX | F12: 525 | G12: 25 개입/1BOX
D13: 일자 | E13: 14 BOX | F13: 280 | G13: 20 개입/1BOX
B14: 코너선반가이드 | C14: 그린 | D14: 라운드 | E14: 4 BOX | F14: 1250 | G14: 250
D15: 일자선반용 | E15: X
C16: 블랙 | D16: 라운드 | E16: 2 BOX | F16: 500 | G16: 250
D17: 일자선반용 | E17: X
B18: 선반브라켓 | C18: 크롬 | E18: 4 BOX | F18: 1600 | G18: 400 개입/1BOX
C19: 블랙 | E19: 8 BOX | F19: 1824 | G19: 228 개입/1BOX
B28: 박스 | C28: 일자선반 | D28: 인박스 | F28: OK
B29: 박스 | C29: 일자선반 | D29: 카튼박스 | F29: OK
B30: 박스 | C30: 코너선반 | D30: 인박스 | F30: X
B31: 박스 | C31: 코너선반 | D31: 카튼박스 | F31: 100
B32: 유리선반 | C32: 블랙 | D32: 오각 | E32: 46 BOX | F32: 1150
B33: 유리선반 | C33: 블랙 | D33: 삼각(라운드) | E33: 13 BOX | F33: 325
B34: 유리선반 | C34: 블랙 | D34: 일자 | E34: 10 BOX | F34: 200
B35: 유리선반 | C35: 그린 | D35: 오각 | E35: 34 BOX | F35: 850
B36: 유리선반 | C36: 그린 | D36: 삼각(라운드) | E36: 21 BOX | F36: 525
B37: 유리선반 | C37: 그린 | D37: 일자 | E37: 14 BOX | F37: 280
B38: 코너선반가이드 | C38: 그린 | D38: 라운드 | E38: 4 BOX | F38: 1250
B39: 코너선반가이드 | C39: 그린 | D39: 일자선반용 | E39: X
B40: 코너선반가이드 | C40: 블랙 | D40: 라운드 | E40: 2 BOX | F40: 500
B41: 코너선반가이드 | C41: 블랙 | D41: 일자선반용 | E41: X
B42: 선반브라켓 | C42: 크롬 | E42: 4 BOX | F42: 1600
B43: 선반브라켓 | C43: 블랙 | E43: 8 BOX | F43: 1824
B47: bom | C47: 블랙코너선반 | D47: 블랙삼각선반 | E47: 블랙코너선반가이드 | F47: 블랙선반브라켓 | G47: 비닐 | H47: 칼브럭피스
D48: 1 | E48: 1 | F48: 2 | G48: 1 | H48: 1
B49: bom | C49: 블랙일자선반 | D49: 블랙일자선반 | E49: 블랙일자선반가이드 | F49: 블랙선반브라켓 | G49: 비닐 | H49: 칼브럭피스
D50: 1 | E50: 2 | F50: 2 | G50: 1 | H50: 1
B51: bom | C51: 블랙오각선반 | D51: 블랙오각선반 | E51: 블랙일자선반가이드 | F51: 블랙선반브라켓 | G51: 비닐 | H51: 칼브럭피스
D52: 1 | E52: 1 | F52: 2 | G52: 1 | H52: 1
B53: bom | C53: 코너선반 | D53: 그린삼각선반 | E53: 크롬코너선반가이드 | F53: 크롬선반브라켓 | G53: 비닐 | H53: 칼브럭피스
...

Sheet 완제품_출하관리
A1: 완제품 출하 관리
